Workbook

Sheet Repeated measurements
N1: These values are in M2 of leaf area, not basal area
A2: population | B2: elevation | C2: genotype | D2: Replicate # | E2: am.pm | F2: date | G2: treatment | H2: rh (%) | I2: Tair (oC) | J2: Tleaf (oC) | K2: vpd (kPa) | L2: gsw.(mol m-2 s-1) | M2: gsw.(mmol m-2 s-1) | N2: E.(mmol m-2 s-1) | O2: E (mol m-2 s-1) | P2: E (g m-2 s-1) | Q2: E (kg m-2 s-1) | R2: E (kg m-2 hr-1) | S2: Total leaf area (m2) | T2: Al:Ab (m2 cm-2) | U2: Al:Ab (m2 m-2) | V2: Ypd (MPa) | W2: Ymd (MPa) | X2: Delta Y (MPa) | Y2: K (Kg hr-1 MPa-1 m-2) | Z2: K (Kg hr-1 MPa-1 m-2) per BA | AA2: K (mmol s-1 MPa-1 m-2) per LA | AB2: K (mmol s-1 MPa-1 m-2) per BA
A3: CCR-COL | B3: 72 | C3: 156 | D3: 43 | E3: am | F3: 45127 | G3: predrought | H3: 25.5 | I3: 38.26 | J3: 33.03 | K3: 3.33 | L3: 0.24 | M3: =L3*1000 -> 240 | N3: 7.42 | O3: =N3/1000 -> 0.00742 | P3: =O3*18 -> 0.13356 | Q3: =P3/1000 -> 0.00013356 | R3: =Q3*3600 -> 0.480816 | S3: 18.53 | T3: 3.87 | U3: =T3*10000 -> 38700 | V3: -0.41 | W3: -2.53 | X3: =V3-W3 -> 2.12 | Y3: =R3/X3 -> 0.2268 | Z3: =Y3*U3 -> 8777.16 | AA3: =Y3 * 1000 * 1000 / 18.01528 / 3600 -> 3.4970314 | AB3: =AA3*U3 -> 135335.12
A4: CCR-COL | B4: 72 | C4: 156 | D4: 44 | E4: am | F4: 45128 | G4: predrought | H4: 32.18 | I4: 36.76 | J4: 33.22 | K4: 3.11 | L4: 0.24 | M4: =L4*1000 -> 240 | N4: 6.72 | O4: =N4/1000 -> 0.00672 | P4: =O4*18 -> 0.12096 | Q4: =P4/1000 -> 0.00012096 | R4: =Q4*3600 -> 0.435456 | S4: 5.08 | T4: 1.59 | U4: =T4*10000 -> 15900 | V4: -0.58 | W4: -2.34 | X4: =V4-W4 -> 1.76 | Y4: =R4/X4 -> 0.24741818 | Z4: =Y4*U4 -> 3933.9491 | AA4: =Y4 * 1000 * 1000 / 18.01528 / 3600 -> 3.8149434 | AB4: =AA4*U4 -> 60657.599
A5: CCR-COL | B5: 72 | C5: 156 | D5: 45 | E5: am | F5: 45127 | G5: predrought | H5: 21 | I5: 40.22 | J5: 33.77 | K5: 3.69 | L5: 0.36 | M5: =L5*1000 -> 360 | N5: 12.54 | O5: =N5/1000 -> 0.01254 | P5: =O5*18 -> 0.22572 | Q5: =P5/1000 -> 0.00022572 | R5: =Q5*3600 -> 0.812592 | S5: 13.38 | T5: 3.64 | U5: =T5*10000 -> 36400 | V5: -0.49 | W5: -1.96 | X5: =V5-W5 -> 1.47 | Y5: =R5/X5 -> 0.55278367 | Z5: =Y5*U5 -> 20121.326 | AA5: =Y5 * 1000 * 1000 / 18.01528 / 3600 -> 8.5233768 | AB5: =AA5*U5 -> 310250.92
A6: CCR-COL | B6: 72 | C6: 149 | D6: 46 | E6: am | F6: 45127 | G6: predrought | H6: 23.12 | I6: 38.65 | J6: 33.68 | K6: 3.64 | L6: 0.29 | M6: =L6*1000 -> 290 | N6: 9.89 | O6: =N6/1000 -> 0.00989 | P6: =O6*18 -> 0.17802 | Q6: =P6/1000 -> 0.00017802 | R6: =Q6*3600 -> 0.640872 | S6: 10.99 | T6: 2.05 | U6: =T6*10000 -> 20500 | V6: -0.5 | W6: -2.96 | X6: =V6-W6 -> 2.46 | Y6: =R6/X6 -> 0.26051707 | Z6: =Y6*U6 -> 5340.6 | AA6: =Y6 * 1000 * 1000 / 18.01528 / 3600 -> 4.0169153 | AB6: =AA6*U6 -> 82346.763
A7: CCR-COL | B7: 72 | C7: 149 | D7: 47 | E7: am | F7: 45128 | G7: predrought | H7: 35.37 | I7: 34.49 | J7: 31.41 | K7: 2.67 | L7: 0.3 | M7: =L7*1000 -> 300 | N7: 7.64 | O7: =N7/1000 -> 0.00764 | P7: =O7*18 -> 0.13752 | Q7: =P7/1000 -> 0.00013752 | R7: =Q7*3600 -> 0.495072 | S7: 10.98 | T7: 2.51 | U7: =T7*10000 -> 25100 | V7: -0.58 | W7: -2.41 | X7: =V7-W7 -> 1.83 | Y7: =R7/X7 -> 0.27053115 | Z7: =Y7*U7 -> 6790.3318 | AA7: =Y7 * 1000 * 1000 / 18.01528 / 3600 -> 4.1713224 | AB7: =AA7*U7 -> 104700.19
A8: CCR-COL | B8: 72 | C8: 149 | D8: 48 | E8: am | F8: 45128 | G8: predrought | H8: 33.08 | I8: 36.29 | J8: 33.43 | K8: 3.16 | L8: 0.19 | M8: =L8*1000 -> 190 | N8: 5.5 | O8: =N8/1000 -> 0.0055 | P8: =O8*18 -> 0.099 | Q8: =P8/1000 -> 9.9e-05 | R8: =Q8*3600 -> 0.3564 | S8: 17.25 | T8: 2.85 | U8: =T8*10000 -> 28500 | V8: -0.81 | W8: -2.7 | X8: =V8-W8 -> 1.89 | Y8: =R8/X8 -> 0.18857143 | Z8: =Y8*U8 -> 5374.2857 | AA8: =Y8 * 1000 * 1000 / 18.01528 / 3600 -> 2.9075847 | AB8: =AA8*U8 -> 82866.164
A9: CCR-COL | B9: 72 | C9: 152 | D9: 49 | E9: am | F9: 45128 | G9: predrought | H9: 37.77 | I9: 32.81 | J9: 29.61 | K9: 2.27 | L9: 0.43 | M9: =L9*1000 -> 430 | N9: 9.19 | O9: =N9/1000 -> 0.00919 | P9: =O9*18 -> 0.16542 | Q9: =P9/1000 -> 0.00016542 | R9: =Q9*3600 -> 0.595512 | S9: 16.68 | T9: 2.78 | U9: =T9*10000 -> 27800 | V9: -0.61 | W9: -2.57 | X9: =V9-W9 -> 1.96 | Y9: =R9/X9 -> 0.30383265 | Z9: =Y9*U9 -> 8446.5478 | AA9: =Y9 * 1000 * 1000 / 18.01528 / 3600 -> 4.6847986 | AB9: =AA9*U9 -> 130237.4
A10: CCR-COL | B10: 72 | C10: 152 | D10: 50 | E10: am | F10: 45128 | G10: predrought | H10: 33.39 | I10: 36.27 | J10: 31.57 | K10: 2.63 | L10: 0.41 | M10: =L10*1000 -> 410 | N10: 10.16 | O10: =N10/1000 -> 0.01016 | P10: =O10*18 -> 0.18288 | Q10: =P10/1000 -> 0.00018288 | R10: =Q10*3600 -> 0.658368 | S10: 29.47 | T10: 3.96 | U10: =T10*10000 -> 39600 | V10: -0.92 | W10: -2.25 | X10: =V10-W10 -> 1.33 | Y10: =R10/X10 -> 0.49501353 | Z10: =Y10*U10 -> 19602.536 | AA10: =Y10 * 1000 * 1000 / 18.01528 / 3600 -> 7.6326185 | AB10: =AA10*U10 -> 302251.69
A11: CCR-COL | B11: 72 | C11: 152 | D11: 51 | E11: am | F11: 45128 | G11: predrought | H11: 32.14 | I11: 36.8 | J11: 32.39 | K11: 2.87 | L11: 0.39 | M11: =L11*1000 -> 390 | N11: 10.54 | O11: =N11/1000 -> 0.01054 | P11: =O11*18 -> 0.18972 | Q11: =P11/1000 -> 0.00018972 | R11: =Q11*3600 -> 0.682992 | S11: 11.56 | T11: 1.91 | U11: =T11*10000 -> 19100 | V11: -0.85 | W11: -2.76 | X11: =V11-W11 -> 1.91 | Y11: =R11/X11 -> 0.35758743 | Z11: =Y11*U11 -> 6829.92 | AA11: =Y11 * 1000 * 1000 / 18.01528 / 3600 -> 5.5136441 | AB11: =AA11*U11 -> 105310.6
A12: CCR-COL | B12: 72 | C12: 155 | D12: 58 | E12: am | F12: 45128 | G12: predrought | H12: 35.9 | I12: 34.13 | J12: 31.69 | K12: 2.75 | L12: 0.24 | M12: =L12*1000 -> 240 | N12: 6.17 | O12: =N12/1000 -> 0.00617 | P12: =O12*18 -> 0.11106 | Q12: =P12/1000 -> 0.00011106 | R12: =Q12*3600 -> 0.399816 | S12: 25.14 | T12: 4.53 | U12: =T12*10000 -> 45300 | V12: -0.83 | W12: -2.87 | X12: =V12-W12 -> 2.04 | Y12: =R12/X12 -> 0.19598824 | Z12: =Y12*U12 -> 8878.2671 | AA12: =Y12 * 1000 * 1000 / 18.01528 / 3600 -> 3.0219445 | AB12: =AA12*U12 -> 136894.09
A13: CCR-COL | B13: 72 | C13: 155 | D13: 59 | E13: am | F13: 45127 | G13: predrought | H13: 27.18 | I13: 35.53 | J13: 32.08 | K13: 3.2 | L13: 0.25 | M13: =L13*1000 -> 250 | N13: 7.52 | O13: =N13/1000 -> 0.00752 | P13: =O13*18 -> 0.13536 | Q13: =P13/1000 -> 0.00013536 | R13: =Q13*3600 -> 0.487296 | S13: 16.94 | T13: 3.17 | U13: =T13*10000 -> 31700 | V13: -0.42 | W13: -2.19 | X13: =V13-W13 -> 1.77 | Y13: =R13/X13 -> 0.27530847 | Z13: =Y13*U13 -> 8727.2786 | AA13: =Y13 * 1000 * 1000 / 18.01528 / 3600 -> 4.2449841 | AB13: =AA13*U13 -> 134565.99
A14: CCR-COL | B14: 72 | C14: 155 | D14: 60 | E14: am | F14: 45128 | G14: predrought | H14: 34.94 | I14: 35.16 | J14: 32.16 | K14: 2.82 | L14: 0.2 | M14: =L14*1000 -> 200 | N14: 5.24 | O14: =N14/1000 -> 0.00524 | P14: =O14*18 -> 0.09432 | Q14: =P14/1000 -> 9.432e-05 | R14: =Q14*3600 -> 0.339552 | S14: 22.24 | T14: 4.22 | U14: =T14*10000 -> 42200 | V14: -0.47 | W14: -2.49 | X14: =V14-W14 -> 2.02 | Y14: =R14/X14 -> 0.16809505 | Z14: =Y14*U14 -> 7093.6111 | AA14: =Y14 * 1000 * 1000 / 18.01528 / 3600 -> 2.5918592 | AB14: =AA14*U14 -> 109376.46
... A122: TSZ-SAN | B122: 1212 | C122: 10 | D122: 42 | E122: pm | F122: 45128 | G122: predrought | H122: 14.29 | I122: 46.54 | J122: 40.97 | K122: 6.29 | L122: 0.14 | M122: =L122*1000 -> 140 | N122: 8.03 | O122: =N122/1000 -> 0.00803 | P122: =O122*18 -> 0.14454 | Q122: =P122/1000 -> 0.00014454 | R122: =Q122*3600 -> 0.520344 | S122: 14.52 | T122: 3.06 | U122: =T122*10000 -> 30600 | V122: -0.59 | W122: -2.29 | X122: =V122-W122 -> 1.7 | Y122: =R122/X122 -> 0.30608471 | Z122: =Y122*U122 -> 9366.192 | AA122: =Y122 * 1000 * 1000 / 18.01528 / 3600 -> 4.7195231 | AB122: =AA122*U122 -> 144417.41
M123: =L123*1000 -> 0 | Z123: =Y123*U123 -> 0 | AA123: =Y123 * 1000 * 1000 / 18.01528 / 3600 -> 0 | AB123: =AA123*U123 -> 0
A124: CCR-COL | B124: 72 | C124: 156 | D124: 43 | E124: am | F124: 45147 | G124: predrought | H124: 35.85 | I124: 35.96 | J124: 30.86 | K124: 2.34 | L124: 0.3 | M124: =L124*1000 -> 300 | N124: 6.56 | O124: =N124/1000 -> 0.00656 | P124: =O124*18 -> 0.11808 | Q124: =P124/1000 -> 0.00011808 | R124: =Q124*3600 -> 0.425088 | S124: 18.53 | T124: 3.87 | U124: =T124*10000 -> 38700 | V124: -0.66 | W124: -2.21 | X124: =V124-W124 -> 1.55 | Y124: =R124/X124 -> 0.27425032 | Z124: =Y124*U124 -> 10613.487 | AA124: =Y124 * 1000 * 1000 / 18.01528 / 3600 -> 4.2286684 | AB124: =AA124*U124 -> 163649.47
A125: CCR-COL | B125: 72 | C125: 156 | D125: 44 | E125: am | F125: 45148 | G125: predrought | H125: 29.74 | I125: 35.96 | J125: 31 | K125: 2.73 | L125: 0.29 | M125: =L125*1000 -> 290 | N125: 7.54 | O125: =N125/1000 -> 0.00754 | P125: =O125*18 -> 0.13572 | Q125: =P125/1000 -> 0.00013572 | R125: =Q125*3600 -> 0.488592 | S125: 5.08 | T125: 1.59 | U125: =T125*10000 -> 15900 | V125: -0.77 | W125: -2.28 | X125: =V125-W125 -> 1.51 | Y125: =R125/X125 -> 0.32357086 | Z125: =Y125*U125 -> 5144.7767 | AA125: =Y125 * 1000 * 1000 / 18.01528 / 3600 -> 4.9891423 | AB125: =AA125*U125 -> 79327.362
A126: CCR-COL | B126: 72 | C126: 156 | D126: 45 | E126: am | F126: 45147 | G126: predrought | H126: 33.9 | I126: 37.03 | J126: 31.92 | K126: 2.61 | L126: 0.38 | M126: =L126*1000 -> 380 | N126: 9.23 | O126: =N126/1000 -> 0.00923 | P126: =O126*18 -> 0.16614 | Q126: =P126/1000 -> 0.00016614 | R126: =Q126*3600 -> 0.598104 | S126: 13.38 | T126: 3.64 | U126: =T126*10000 -> 36400 | V126: -0.51 | W126: -1.92 | X126: =V126-W126 -> 1.41 | Y126: =R126/X126 -> 0.42418723 | Z126: =Y126*U126 -> 15440.415 | AA126: =Y126 * 1000 * 1000 / 18.01528 / 3600 -> 6.5405471 | AB126: =AA126*U126 -> 238075.91
A127: CCR-COL | B127: 72 | C127: 149 | D127: 46 | E127: am | F127: 45147 | G127: predrought | H127: 35.57 | I127: 36.04 | J127: 31.33 | K127: 2.46 | L127: 0.45 | M127: =L127*1000 -> 450 | N127: 10.58 | O127: =N127/1000 -> 0.01058 | P127: =O127*18 -> 0.19044 | Q127: =P127/1000 -> 0.00019044 | R127: =Q127*3600 -> 0.685584 | S127: 10.99 | T127: 2.05 | U127: =T127*10000 -> 20500 | V127: -0.62 | W127: -2.1 | X127: =V127-W127 -> 1.48 | Y127: =R127/X127 -> 0.46323243 | Z127: =Y127*U127 -> 9496.2649 | AA127: =Y127 * 1000 * 1000 / 18.01528 / 3600 -> 7.1425854 | AB127: =AA127*U127 -> 146423
A128: CCR-COL | B128: 72 | C128: 149 | D128: 47 | E128: am | F128: 45148 | G128: predrought | H128: 32.18 | I128: 34.9 | J128: 30.72 | K128: 2.63 | L128: 0.35 | M128: =L128*1000 -> 350 | N128: 8.81 | O128: =N128/1000 -> 0.00881 | P128: =O128*18 -> 0.15858 | Q128: =P128/1000 -> 0.00015858 | R128: =Q128*3600 -> 0.570888 | S128: 10.98 | T128: 2.51 | U128: =T128*10000 -> 25100 | V128: -0.44 | W128: -2.3 | X128: =V128-W128 -> 1.86 | Y128: =R128/X128 -> 0.30692903 | Z128: =Y128*U128 -> 7703.9187 | AA128: =Y128 * 1000 * 1000 / 18.01528 / 3600 -> 4.7325417 | AB128: =AA128*U128 -> 118786.8
A129: CCR-COL | B129: 72 | C129: 149 | D129: 48 | E129: am | F129: 45148 | G129: predrought | H129: 30.89 | I129: 35.2 | J129: 31.5 | K129: 2.87 | L129: 0.33 | M129: =L129*1000 -> 330 | N129: 8.92 | O129: =N129/1000 -> 0.00892 | P129: =O129*18 -> 0.16056 | Q129: =P129/1000 -> 0.00016056 | R129: =Q129*3600 -> 0.578016 | S129: 17.25 | T129: 2.85 | U129: =T129*10000 -> 28500 | V129: -0.61 | W129: -2.2 | X129: =V129-W129 -> 1.59 | Y129: =R129/X129 -> 0.36353208 | Z129: =Y129*U129 -> 10360.664 | AA129: =Y129 * 1000 * 1000 / 18.01528 / 3600 -> 5.6053046 | AB129: =AA129*U129 -> 159751.18
A130: CCR-COL | B130: 72 | C130: 152 | D130: 49 | E130: am | F130: 45147 | G130: predrought | H130: 36.61 | I130: 34.85 | J130: 29.61 | K130: 2.11 | L130: 0.45 | M130: =L130*1000 -> 450 | N130: 8.91 | O130: =N130/1000 -> 0.00891 | P130: =O130*18 -> 0.16038 | Q130: =P130/1000 -> 0.00016038 | R130: =Q130*3600 -> 0.577368 | S130: 16.68 | T130: 2.78 | U130: =T130*10000 -> 27800 | V130: -0.93 | W130: -1.75 | X130: =V130-W130 -> 0.82 | Y130: =R130/X130 -> 0.70410732 | Z130: =Y130*U130 -> 19574.183 | AA130: =Y130 * 1000 * 1000 / 18.01528 / 3600 -> 10.856638 | AB130: =AA130*U130 -> 301814.52
A131: CCR-COL | B131: 72 | C131: 152 | D131: 50 | E131: am | F131: 45148 | G131: predrought | H131: 31.37 | I131: 35.23 | J131: 30.47 | K131: 2.57 | L131: 0.32 | M131: =L131*1000 -> 320 | N131: 7.72 | O131: =N131/1000 -> 0.00772 | P131: =O131*18 -> 0.13896 | Q131: =P131/1000 -> 0.00013896 | R131: =Q131*3600 -> 0.500256 | S131: 29.47 | T131: 3.96 | U131: =T131*10000 -> 39600 | V131: -0.61 | W131: -2.42 | X131: =V131-W131 -> 1.81 | Y131: =R131/X131 -> 0.27638453 | Z131: =Y131*U131 -> 10944.827 | AA131: =Y131 * 1000 * 1000 / 18.01528 / 3600 -> 4.2615758 | AB131: =AA131*U131 -> 168758.4
A132: CCR-COL | B132: 72 | C132: 152 | D132: 51 | E132: am | F132: 45148 | G132: predrought | H132: 30.61 | I132: 36 | J132: 31.25 | K132: 2.74 | L132: 0.38 | M132: =L132*1000 -> 380 | N132: 9.81 | O132: =N132/1000 -> 0.00981 | P132: =O132*18 -> 0.17658 | Q132: =P132/1000 -> 0.00017658 | R132: =Q132*3600 -> 0.635688 | S132: 11.56 | T132: 1.91 | U132: =T132*10000 -> 19100 | V132: -0.712 | W132: -1.64 | X132: =V132-W132 -> 0.928 | Y132: =R132/X132 -> 0.68500862 | Z132: =Y132*U132 -> 13083.665 | AA132: =Y132 * 1000 * 1000 / 18.01528 / 3600 -> 10.562155 | AB132: =AA132*U132 -> 201737.15
A133: CCR-COL | B133: 72 | C133: 155 | D133: 58 | E133: am | F133: 45148 | G133: predrought | H133: 31.28 | I133: 35.33 | J133: 31.05 | K133: 2.72 | L133: 0.26 | M133: =L133*1000 -> 260 | N133: 6.58 | O133: =N133/1000 -> 0.00658 | P133: =O133*18 -> 0.11844 | Q133: =P133/1000 -> 0.00011844 | R133: =Q133*3600 -> 0.426384 | S133: 25.14 | T133: 4.53 | U133: =T133*10000 -> 45300 | V133: -0.73 | W133: -1.74 | X133: =V133-W133 -> 1.01 | Y133: =R133/X133 -> 0.42216238 | Z133: =Y133*U133 -> 19123.956 | AA133: =Y133 * 1000 * 1000 / 18.01528 / 3600 -> 6.5093258 | AB133: =AA133*U133 -> 294872.46
A134: CCR-COL | B134: 72 | C134: 155 | D134: 59 | E134: am | F134: 45147 | G134: predrought | H134: 37.19 | I134: 35 | J134: 30.76 | K134: 2.35 | L134: 0.32 | M134: =L134*1000 -> 320 | N134: 7.09 | O134: =N134/1000 -> 0.00709 | P134: =O134*18 -> 0.12762 | Q134: =P134/1000 -> 0.00012762 | R134: =Q134*3600 -> 0.459432 | S134: 16.94 | T134: 3.17 | U134: =T134*10000 -> 31700 | V134: -0.52 | W134: -2.02 | X134: =V134-W134 -> 1.5 | Y134: =R134/X134 -> 0.306288 | Z134: =Y134*U134 -> 9709.3296 | AA134: =Y134 * 1000 * 1000 / 18.01528 / 3600 -> 4.7226577 | AB134: =AA134*U134 -> 149708.25
A135: CCR-COL | B135: 72 | C135: 155 | D135: 60 | E135: am | F135: 45148 | G135: predrought | H135: 31.82 | I135: 34.81 | J135: 30.63 | K135: 2.63 | L135: 0.2 | M135: =L135*1000 -> 200 | N135: 5.01 | O135: =N135/1000 -> 0.00501 | P135: =O135*18 -> 0.09018 | Q135: =P135/1000 -> 9.018e-05 | R135: =Q135*3600 -> 0.324648 | S135: 22.24 | T135: 4.22 | U135: =T135*10000 -> 42200 | V135: -0.49 | W135: -2.45 | X135: =V135-W135 -> 1.96 | Y135: =R135/X135 -> 0.16563673 | Z135: =Y135*U135 -> 6989.8702 | AA135: =Y135 * 1000 * 1000 / 18.01528 / 3600 -> 2.5539544 | AB135: =AA135*U135 -> 107776.88
... A243: TSZ-SAN | B243: 1212 | C243: 10 | D243: 42 | E243: pm | F243: 45148 | G243: predrought | H243: 19.53 | I243: 43.13 | J243: 36.38 | K243: 4.37 | L243: 0.24 | M243: =L243*1000 -> 240 | N243: 9.94 | O243: =N243/1000 -> 0.00994 | P243: =O243*18 -> 0.17892 | Q243: =P243/1000 -> 0.00017892 | R243: =Q243*3600 -> 0.644112 | S243: 14.52 | T243: 3.06 | U243: =T243*10000 -> 30600 | V243: -0.51 | W243: -2.25 | X243: =V243-W243 -> 1.74 | Y243: =R243/X243 -> 0.37017931 | Z243: =Y243*U243 -> 11327.487 | AA243: =Y243 * 1000 * 1000 / 18.01528 / 3600 -> 5.7077984 | AB243: =AA243*U243 -> 174658.63
M244: =L244*1000 -> 0 | Z244: =Y244*U244 -> 0 | AA244: =Y244 * 1000 * 1000 / 18.01528 / 3600 -> 0 | AB244: =AA244*U244 -> 0
A245: CCR-COL | B245: 72 | C245: 156 | D245: 43 | E245: am | F245: 45155 | G245: predrought | H245: 33.15 | I245: 35.95 | J245: 32.65 | K245: 2.98 | L245: 0.26 | M245: =L245*1000 -> 260 | N245: 7.41 | O245: =N245/1000 -> 0.00741 | P245: =O245*18 -> 0.13338 | Q245: =P245/1000 -> 0.00013338 | R245: =Q245*3600 -> 0.480168 | S245: 18.53 | T245: 3.87 | U245: =T245*10000 -> 38700 | V245: -0.36 | W245: -1.89 | X245: =V245-W245 -> 1.53 | Y245: =R245/X245 -> 0.31383529 | Z245: =Y245*U245 -> 12145.426 | AA245: =Y245 * 1000 * 1000 / 18.01528 / 3600 -> 4.8390295 | AB245: =AA245*U245 -> 187270.44
A246: CCR-COL | B246: 72 | C246: 156 | D246: 44 | E246: am | F246: 45154 | G246: predrought | H246: 32.33 | I246: 37.69 | J246: 32.87 | K246: 2.89 | L246: 0.39 | M246: =L246*1000 -> 390 | N246: 10.66 | O246: =N246/1000 -> 0.01066 | P246: =O246*18 -> 0.19188 | Q246: =P246/1000 -> 0.00019188 | R246: =Q246*3600 -> 0.690768 | S246: 5.08 | T246: 1.59 | U246: =T246*10000 -> 15900 | V246: -0.88 | W246: -1.81 | X246: =V246-W246 -> 0.93 | Y246: =R246/X246 -> 0.74276129 | Z246: =Y246*U246 -> 11809.905 | AA246: =Y246 * 1000 * 1000 / 18.01528 / 3600 -> 11.452644 | AB246: =AA246*U246 -> 182097.03
A247: CCR-COL | B247: 72 | C247: 156 | D247: 45 | E247: am | F247: 45155 | G247: predrought | H247: 30.24 | I247: 37.18 | J247: 32.67 | K247: 3.02 | L247: 0.28 | M247: =L247*1000 -> 280 | N247: 8.07 | O247: =N247/1000 -> 0.00807 | P247: =O247*18 -> 0.14526 | Q247: =P247/1000 -> 0.00014526 | R247: =Q247*3600 -> 0.522936 | S247: 13.38 | T247: 3.64 | U247: =T247*10000 -> 36400 | V247: -0.83 | W247: -2.33 | X247: =V247-W247 -> 1.5 | Y247: =R247/X247 -> 0.348624 | Z247: =Y247*U247 -> 12689.914 | AA247: =Y247 * 1000 * 1000 / 18.01528 / 3600 -> 5.3754369 | AB247: =AA247*U247 -> 195665.9
A248: CCR-COL | B248: 72 | C248: 149 | D248: 46 | E248: am | F248: 45155 | G248: predrought | H248: 33.26 | I248: 36.27 | J248: 32.39 | K248: 2.86 | L248: 0.38 | M248: =L248*1000 -> 380 | N248: 10.4 | O248: =N248/1000 -> 0.0104 | P248: =O248*18 -> 0.1872 | Q248: =P248/1000 -> 0.0001872 | R248: =Q248*3600 -> 0.67392 | S248: 10.99 | T248: 2.05 | U248: =T248*10000 -> 20500 | V248: -0.61 | W248: -1.66 | X248: =V248-W248 -> 1.05 | Y248: =R248/X248 -> 0.64182857 | Z248: =Y248*U248 -> 13157.486 | AA248: =Y248 * 1000 * 1000 / 18.01528 / 3600 -> 9.896361 | AB248: =AA248*U248 -> 202875.4
A249: CCR-COL | B249: 72 | C249: 149 | D249: 47 | E249: am | F249: 45154 | G249: predrought | H249: 47.13 | I249: 32.57 | J249: 29.99 | K249: 1.93 | L249: 0.38 | M249: =L249*1000 -> 380 | N249: 7 | O249: =N249/1000 -> 0.007 | P249: =O249*18 -> 0.126 | Q249: =P249/1000 -> 0.000126 | R249: =Q249*3600 -> 0.4536 | S249: 10.98 | T249: 2.51 | U249: =T249*10000 -> 25100 | V249: -0.75 | W249: -2.13 | X249: =V249-W249 -> 1.38 | Y249: =R249/X249 -> 0.32869565 | Z249: =Y249*U249 -> 8250.2609 | AA249: =Y249 * 1000 * 1000 / 18.01528 / 3600 -> 5.0681615 | AB249: =AA249*U249 -> 127210.85
A250: CCR-COL | B250: 72 | C250: 149 | D250: 48 | E250: am | F250: 45154 | G250: predrought | H250: 40.59 | I250: 35.51 | J250: 32.54 | K250: 2.56 | L250: 0.37 | M250: =L250*1000 -> 370 | N250: 8.95 | O250: =N250/1000 -> 0.00895 | P250: =O250*18 -> 0.1611 | Q250: =P250/1000 -> 0.0001611 | R250: =Q250*3600 -> 0.57996 | S250: 17.25 | T250: 2.85 | U250: =T250*10000 -> 28500 | V250: -0.81 | W250: -2.18 | X250: =V250-W250 -> 1.37 | Y250: =R250/X250 -> 0.42332847 | Z250: =Y250*U250 -> 12064.861 | AA250: =Y250 * 1000 * 1000 / 18.01528 / 3600 -> 6.5273058 | AB250: =AA250*U250 -> 186028.21
A251: CCR-COL | B251: 72 | C251: 152 | D251: 49 | E251: am | F251: 45155 | G251: predrought | H251: 36.22 | I251: 33.96 | J251: 29.92 | K251: 2.31 | L251: 0.34 | M251: =L251*1000 -> 340 | N251: 7.21 | O251: =N251/1000 -> 0.00721 | P251: =O251*18 -> 0.12978 | Q251: =P251/1000 -> 0.00012978 | R251: =Q251*3600 -> 0.467208 | S251: 16.68 | T251: 2.78 | U251: =T251*10000 -> 27800 | V251: -0.78 | W251: -1.66 | X251: =V251-W251 -> 0.88 | Y251: =R251/X251 -> 0.53091818 | Z251: =Y251*U251 -> 14759.525 | AA251: =Y251 * 1000 * 1000 / 18.01528 / 3600 -> 8.1862326 | AB251: =AA251*U251 -> 227577.27
A252: CCR-COL | B252: 72 | C252: 152 | D252: 50 | E252: am | F252: 45154 | G252: predrought | H252: 44.3 | I252: 34.53 | J252: 30.79 | K252: 2.01 | L252: 0.24 | M252: =L252*1000 -> 240 | N252: 4.5 | O252: =N252/1000 -> 0.0045 | P252: =O252*18 -> 0.081 | Q252: =P252/1000 -> 8.1e-05 | R252: =Q252*3600 -> 0.2916 | S252: 29.47 | T252: 3.96 | U252: =T252*10000 -> 39600 | V252: -0.32 | W252: -1.74 | X252: =V252-W252 -> 1.42 | Y252: =R252/X252 -> 0.20535211 | Z252: =Y252*U252 -> 8131.9437 | AA252: =Y252 * 1000 * 1000 / 18.01528 / 3600 -> 3.1663262 | AB252: =AA252*U252 -> 125386.52
A253: CCR-COL | B253: 72 | C253: 152 | D253: 51 | E253: am | F253: 45154 | G253: predrought | H253: 31.86 | I253: 37.85 | J253: 32.25 | K253: 2.73 | L253: 0.49 | M253: =L253*1000 -> 490 | N253: 12.81 | O253: =N253/1000 -> 0.01281 | P253: =O253*18 -> 0.23058 | Q253: =P253/1000 -> 0.00023058 | R253: =Q253*3600 -> 0.830088 | S253: 11.56 | T253: 1.91 | U253: =T253*10000 -> 19100 | V253: -0.37 | W253: -1.51 | X253: =V253-W253 -> 1.14 | Y253: =R253/X253 -> 0.72814737 | Z253: =Y253*U253 -> 13907.615 | AA253: =Y253 * 1000 * 1000 / 18.01528 / 3600 -> 11.227311 | AB253: =AA253*U253 -> 214441.65
A254: CCR-COL | B254: 72 | C254: 155 | D254: 58 | E254: am | F254: 45154 | G254: predrought | H254: 48.61 | I254: 32.26 | J254: 29.94 | K254: 1.88 | L254: 0.22 | M254: =L254*1000 -> 220 | N254: 3.89 | O254: =N254/1000 -> 0.00389 | P254: =O254*18 -> 0.07002 | Q254: =P254/1000 -> 7.002e-05 | R254: =Q254*3600 -> 0.252072 | S254: 25.14 | T254: 4.53 | U254: =T254*10000 -> 45300 | V254: -0.47 | W254: -1.91 | X254: =V254-W254 -> 1.44 | Y254: =R254/X254 -> 0.17505 | Z254: =Y254*U254 -> 7929.765 | AA254: =Y254 * 1000 * 1000 / 18.01528 / 3600 -> 2.6990977 | AB254: =AA254*U254 -> 122269.12
...

Sheet One time measurements
A1: population | B1: elevation | C1: genotype | D1: Replicate # | E1: SLA (mm2 mg-1) | F1: Rooting depth (cm) | G1: Tree height (m)* | H1: Pre drought BA (mm2) | I1: Pre drought BA (m^2) | J1: Post drought BA (mm2) | K1: Ground area (mm2) | L1: Ground area (m^2) | M1: Ground area (ha) | N1: Pre drought Ab:Ag-1 (mm2 mm-2) | O1: Pre drought Ab:Ag-1 (m2 ha-1) | P1: Post drought Ab:Ag-1 (mm2 mm-2) | Q1: Mean leaf width (cm) | R1: Predrought Anet umol m-2 s-1 | S1: Postdrought Anet umol m-2 s-1 | T1: Pre drought Vcmax | U1: Post drought Vcmax | V1: Pre drought jmax | W1: Post drought jmax | X1: Ar (m2) | Y1: Al:Ar (m2 m-2) | Z1: A_l (m^2)
A2: CCR-COL | B2: 72 | C2: 156 | D2: 43 | E2: 8.66 | F2: 27.73 | G2: 1.58 | H2: 479 | I2: =H2/1000000 -> 0.000479 | J2: 827 | K2: 114010 | L2: =K2/1000000 -> 0.11401 | M2: =K2/10000000000 -> 1.1401e-05 | N2: =H2/K2 -> 0.0042013858 | O2: =I2/M2 -> 42.013858 | P2: =J2/K2 -> 0.0072537497 | Q2: 3.885 | R2: 16.178569 | S2: 30.524653 | T2: 67.450591 | U2: 116.61954 | V2: 137.23727 | W2: 240.84449
A3: CCR-COL | B3: 72 | C3: 156 | D3: 44 | E3: 7.83 | F3: 27.73 | G3: 1.64 | H3: 320 | I3: =H3/1000000 -> 0.00032 | J3: 462 | K3: 114010 | L3: =K3/1000000 -> 0.11401 | M3: =K3/10000000000 -> 1.1401e-05 | N3: =H3/K3 -> 0.0028067713 | O3: =I3/M3 -> 28.067713 | P3: =J3/K3 -> 0.0040522761 | Q3: 3.416 | R3: 28.600637 | S3: 25.885301 | T3: 108.988 | U3: 104.89891 | V3: 258.59366 | W3: 229.24093 | X3: 2.89 | Y3: 4.22 | Z3: =Y3*X3 -> 12.1958
A4: CCR-COL | B4: 72 | C4: 156 | D4: 45 | E4: 6.06 | F4: 27.73 | G4: 1.56 | H4: 368 | I4: =H4/1000000 -> 0.000368 | J4: 633 | K4: 114010 | L4: =K4/1000000 -> 0.11401 | M4: =K4/10000000000 -> 1.1401e-05 | N4: =H4/K4 -> 0.003227787 | O4: =I4/M4 -> 32.27787 | P4: =J4/K4 -> 0.0055521445 | Q4: 3.645 | R4: 28.719757 | S4: 28.022467 | T4: 112.73838 | U4: 110.3865 | V4: 288.63489 | W4: 234.18904
A5: CCR-COL | B5: 72 | C5: 149 | D5: 46 | E5: 7.48 | F5: 27.73 | G5: 2.05 | H5: 537 | I5: =H5/1000000 -> 0.000537 | J5: 897 | K5: 114010 | L5: =K5/1000000 -> 0.11401 | M5: =K5/10000000000 -> 1.1401e-05 | N5: =H5/K5 -> 0.0047101131 | O5: =I5/M5 -> 47.101131 | P5: =J5/K5 -> 0.0078677309 | Q5: 3.015 | R5: 23.87606 | S5: 18.782984 | T5: 91.624721 | U5: 106.80594 | V5: 202.21486 | W5: 214.13416 | X5: 7.38 | Y5: 1.52 | Z5: =Y5*X5 -> 11.2176
A6: CCR-COL | B6: 72 | C6: 149 | D6: 47 | E6: 7.28 | F6: 27.73 | G6: 2.18 | H6: 437 | I6: =H6/1000000 -> 0.000437 | J6: 806 | K6: 114010 | L6: =K6/1000000 -> 0.11401 | M6: =K6/10000000000 -> 1.1401e-05 | N6: =H6/K6 -> 0.0038329971 | O6: =I6/M6 -> 38.329971 | P6: =J6/K6 -> 0.0070695553 | Q6: 3.502 | R6: 26.01129 | S6: 27.137131 | T6: 95.498355 | U6: 125.28903 | V6: 224.31991 | W6: 278.66998
A7: CCR-COL | B7: 72 | C7: 149 | D7: 48 | E7: 7.96 | F7: 27.73 | G7: 2.26 | H7: 604 | I7: =H7/1000000 -> 0.000604 | J7: 942 | K7: 114010 | L7: =K7/1000000 -> 0.11401 | M7: =K7/10000000000 -> 1.1401e-05 | N7: =H7/K7 -> 0.0052977809 | O7: =I7/M7 -> 52.977809 | P7: =J7/K7 -> 0.0082624331 | Q7: 4.076 | R7: 18.184514 | S7: 20.087915 | T7: 75.316961 | U7: 103.61852 | V7: 227.6287 | W7: 211.09613
A8: CCR-COL | B8: 72 | C8: 152 | D8: 49 | E8: 6.49 | F8: 27.73 | G8: 1.64 | H8: 600 | I8: =H8/1000000 -> 0.0006 | J8: 1185 | K8: 114010 | L8: =K8/1000000 -> 0.11401 | M8: =K8/10000000000 -> 1.1401e-05 | N8: =H8/K8 -> 0.0052626963 | O8: =I8/M8 -> 52.626963 | P8: =J8/K8 -> 0.010393825 | Q8: 3.327 | R8: 24.03822 | S8: 33.434472 | T8: 96.969494 | U8: 124.45992 | V8: 230.71024 | W8: 253.93187
A9: CCR-COL | B9: 72 | C9: 152 | D9: 50 | E9: 7.36 | F9: 27.73 | G9: 1.6 | H9: 745 | I9: =H9/1000000 -> 0.000745 | J9: 1119 | K9: 114010 | L9: =K9/1000000 -> 0.11401 | M9: =K9/10000000000 -> 1.1401e-05 | N9: =H9/K9 -> 0.0065345145 | O9: =I9/M9 -> 65.345145 | P9: =J9/K9 -> 0.0098149285 | Q9: 3.788 | R9: 30.199045 | S9: 15.628999 | T9: 104.74043 | U9: 58.314139 | V9: 248.08868 | W9: 121.63338
A10: CCR-COL | B10: 72 | C10: 152 | D10: 51 | E10: 6.5 | F10: 27.73 | G10: 1.36 | H10: 604 | I10: =H10/1000000 -> 0.000604 | J10: 1012 | K10: 114010 | L10: =K10/1000000 -> 0.11401 | M10: =K10/10000000000 -> 1.1401e-05 | N10: =H10/K10 -> 0.0052977809 | O10: =I10/M10 -> 52.977809 | P10: =J10/K10 -> 0.0088764143 | Q10: 3.228 | R10: 25.846151 | S10: 34.628875 | T10: 97.555049 | U10: 129.32989 | V10: 230.05252 | W10: 255.64725 | X10: 3.51 | Y10: 5.29 | Z10: =Y10*X10 -> 18.5679
A11: CCR-COL | B11: 72 | C11: 155 | D11: 58 | E11: 8.1 | F11: 27.73 | G11: 1.28 | H11: 555 | I11: =H11/1000000 -> 0.000555 | J11: 827 | K11: 114010 | L11: =K11/1000000 -> 0.11401 | M11: =K11/10000000000 -> 1.1401e-05 | N11: =H11/K11 -> 0.004867994 | O11: =I11/M11 -> 48.67994 | P11: =J11/K11 -> 0.0072537497 | Q11: 3.401 | R11: 31.177421 | S11: 30.633821 | T11: 118.99135 | U11: 136.3944 | V11: 272.74271 | W11: 284.95016
A12: CCR-COL | B12: 72 | C12: 155 | D12: 59 | E12: 10.14 | F12: 27.73 | G12: 1.36 | H12: 535 | I12: =H12/1000000 -> 0.000535 | J12: 948 | K12: 114010 | L12: =K12/1000000 -> 0.11401 | M12: =K12/10000000000 -> 1.1401e-05 | N12: =H12/K12 -> 0.0046925708 | O12: =I12/M12 -> 46.925708 | P12: =J12/K12 -> 0.0083150601 | Q12: 2.888 | R12: 25.160902 | S12: 34.334628 | T12: 97.133775 | U12: 151.12378 | V12: 229.35241 | W12: 349.87139
A13: CCR-COL | B13: 72 | C13: 155 | D13: 60 | E13: 9 | F13: 27.73 | G13: 1.33 | H13: 527 | I13: =H13/1000000 -> 0.000527 | J13: 910 | K13: 114010 | L13: =K13/1000000 -> 0.11401 | M13: =K13/10000000000 -> 1.1401e-05 | N13: =H13/K13 -> 0.0046224015 | O13: =I13/M13 -> 46.224015 | P13: =J13/K13 -> 0.007981756 | Q13: 3.788 | R13: 25.826178 | S13: 35.876412 | T13: 90.459742 | U13: 176.62033 | V13: 221.70858 | W13: 267.82223 | X13: 0.44 | Y13: 23.12 | Z13: =Y13*X13 -> 10.1728
A14: CCR-COL | B14: 72 | C14: 5 | D14: 61 | E14: 6.64 | F14: 27.73 | G14: 1.14 | H14: 306 | I14: =H14/1000000 -> 0.000306 | J14: 437 | K14: 114010 | L14: =K14/1000000 -> 0.11401 | M14: =K14/10000000000 -> 1.1401e-05 | N14: =H14/K14 -> 0.0026839751 | O14: =I14/M14 -> 26.839751 | P14: =J14/K14 -> 0.0038329971 | Q14: 3.323 | R14: 25.282649 | S14: 30.668106 | T14: 91.907939 | U14: 139.97519 | V14: 249.61413 | W14: 308.14072
A15: CCR-COL | B15: 72 | C15: 5 | D15: 63 | E15: 7.06 | F15: 27.73 | G15: 1.44 | H15: 487 | I15: =H15/1000000 -> 0.000487 | J15: 651 | K15: 114010 | L15: =K15/1000000 -> 0.11401 | M15: =K15/10000000000 -> 1.1401e-05 | N15: =H15/K15 -> 0.0042715551 | O15: =I15/M15 -> 42.715551 | P15: =J15/K15 -> 0.0057100254 | Q15: 3.005 | R15: 22.463388 | S15: 25.471402 | T15: 90.759461 | U15: 113.03982 | V15: 207.27798 | W15: 237.66135
A16: CCR-COL | B16: 72 | C16: 5 | D16: 85 | E16: 6.97 | F16: 27.73 | G16: 1.37 | H16: 354 | I16: =H16/1000000 -> 0.000354 | J16: 577 | K16: 114010 | L16: =K16/1000000 -> 0.11401 | M16: =K16/10000000000 -> 1.1401e-05 | N16: =H16/K16 -> 0.0031049908 | O16: =I16/M16 -> 31.049908 | P16: =J16/K16 -> 0.0050609596 | Q16: 3.3 | R16: 18.707497 | S16: 23.516593 | T16: 68.033267 | U16: 111.41609 | V16: 196.07112 | W16: 229.19718 | X16: 4.02 | Y16: 1.95 | Z16: =Y16*X16 -> 7.839
A17: MEAN | B17: =AVERAGE(B2:B16) -> 72 | C17: =AVERAGE(C2:C16) -> 123.4 | D17: =AVERAGE(D2:D16) -> 53.933333 | E17: =AVERAGE(E2:E16) -> 7.5686667 | F17: =AVERAGE(F2:F16) -> 27.73 | G17: =AVERAGE(G2:G16) -> 1.586 | H17: =AVERAGE(H2:H16) -> 497.2 | I17: =AVERAGE(I2:I16) -> 0.0004972 | ... W17: =AVERAGE(W2:W16) -> 247.80202
A18: STDERR | B18: =STDEV(B2:B16)/SQRT(COUNT(B2:B16)) -> 0 | C18: =STDEV(C2:C16)/SQRT(COUNT(C2:C16)) -> 15.835403 | D18: =STDEV(D2:D16)/SQRT(COUNT(D2:D16)) -> 2.8190959 | E18: =STDEV(E2:E16)/SQRT(COUNT(E2:E16)) -> 0.28074029 | F18: =STDEV(F2:F16)/SQRT(COUNT(F2:F16)) -> 9.4950267e-16 | G18: =STDEV(G2:G16)/SQRT(COUNT(G2:G16)) -> 0.086116201 | H18: =STDEV(H2:H16)/SQRT(COUNT(H2:H16)) -> 31.716182 | I18: =STDEV(I2:I16)/SQRT(COUNT(I2:I16)) -> 3.1716182e-05 | ... W18: =STDEV(W2:W16)/SQRT(COUNT(W2:W16)) -> 13.150818
A19: VAR | B19: =_xlfn.VAR.S(B2:B16) -> 0 | C19: =_xlfn.VAR.S(C2:C16) -> 3761.4 | D19: =_xlfn.VAR.S(D2:D16) -> 119.20952 | E19: =_xlfn.VAR.S(E2:E16) -> 1.1822267 | F19: =_xlfn.VAR.S(F2:F16) -> 1.352333e-29 | G19: =_xlfn.VAR.S(G2:G16) -> 0.11124 | H19: =_xlfn.VAR.S(H2:H16) -> 15088.743 | I19: =_xlfn.VAR.S(I2:I16) -> 1.5088743e-08 | ... W19: =_xlfn.VAR.S(W2:W16) -> 2594.1601
A20: JLA-JAK | B20: 1521 | C20: 153 | D20: 69 | E20: 8.01 | F20: 27.73 | G20: 1.43 | H20: 448 | I20: =H20/1000000 -> 0.000448 | J20: 827 | K20: 114010 | L20: =K20/1000000 -> 0.11401 | M20: =K20/10000000000 -> 1.1401e-05 | N20: =H20/K20 -> 0.0039294799 | O20: =I20/M20 -> 39.294799 | P20: =J20/K20 -> 0.0072537497 | Q20: 4.2 | R20: 21.978967 | S20: 26.008329 | T20: 73.008945 | U20: 121.75132 | V20: 195.53022 | W20: 258.52217
A21: JLA-JAK | B21: 1521 | C21: 153 | D21: 76 | E21: 7.44 | F21: 27.73 | G21: 1.42 | H21: 406 | I21: =H21/1000000 -> 0.000406 | J21: 462 | K21: 114010 | L21: =K21/1000000 -> 0.11401 | M21: =K21/10000000000 -> 1.1401e-05 | N21: =H21/K21 -> 0.0035610911 | O21: =I21/M21 -> 35.610911 | P21: =J21/K21 -> 0.0040522761 | Q21: 4.232 | R21: 16.03357 | S21: 21.87495 | T21: 56.721846 | U21: 107.51054 | V21: 195.48355 | W21: 211.41479
A22: JLA-JAK | B22: 1521 | C22: 153 | D22: 90 | E22: 7.98 | F22: 27.73 | G22: 2.16 | H22: 716 | I22: =H22/1000000 -> 0.000716 | J22: 633 | K22: 114010 | L22: =K22/1000000 -> 0.11401 | M22: =K22/10000000000 -> 1.1401e-05 | N22: =H22/K22 -> 0.0062801509 | O22: =I22/M22 -> 62.801509 | P22: =J22/K22 -> 0.0055521445 | Q22: 4.886 | R22: 13.214128 | S22: 21.266593 | T22: 49.657833 | U22: 82.779526 | V22: 112.21444 | W22: 167.74215 | X22: 8.68 | Y22: 0.146 | Z22: =Y22*X22 -> 1.26728
A23: JLA-JAK | B23: 1521 | C23: 155 | D23: 62 | E23: 7 | F23: 27.73 | G23: 1.42 | H23: 267 | I23: =H23/1000000 -> 0.000267 | J23: 897 | K23: 114010 | L23: =K23/1000000 -> 0.11401 | M23: =K23/10000000000 -> 1.1401e-05 | N23: =H23/K23 -> 0.0023418998 | O23: =I23/M23 -> 23.418998 | P23: =J23/K23 -> 0.0078677309 | Q23: 3.635 | R23: 17.259632 | S23: 26.163526 | T23: 98.703484 | U23: 88.525082 | V23: 229.31396 | W23: 177.76821
A24: JLA-JAK | B24: 1521 | C24: 155 | D24: 64 | E24: 7.62 | F24: 27.73 | G24: 1.85 | H24: 306 | I24: =H24/1000000 -> 0.000306 | J24: 806 | K24: 114010 | L24: =K24/1000000 -> 0.11401 | M24: =K24/10000000000 -> 1.1401e-05 | N24: =H24/K24 -> 0.0026839751 | O24: =I24/M24 -> 26.839751 | P24: =J24/K24 -> 0.0070695553 | Q24: 3.7 | R24: 22.789083 | S24: 20.860713 | T24: 104.66246 | U24: 83.918467 | V24: 238.21353 | W24: 172.85719
A25: JLA-JAK | B25: 1521 | C25: 155 | D25: 66 | E25: 8.38 | F25: 27.73 | G25: 1.94 | H25: 469 | I25: =H25/1000000 -> 0.000469 | J25: 942 | K25: 114010 | L25: =K25/1000000 -> 0.11401 | M25: =K25/10000000000 -> 1.1401e-05 | N25: =H25/K25 -> 0.0041136742 | O25: =I25/M25 -> 41.136742 | P25: =J25/K25 -> 0.0082624331 | Q25: 4.45 | R25: 27.04496 | S25: 23.181529 | T25: 118.2256 | U25: 121.8895 | V25: 278.12665 | W25: 268.11936 | X25: 1.33 | Y25: 2.33 | Z25: =Y25*X25 -> 3.0989
A26: JLA-JAK | B26: 1521 | C26: 156 | D26: 71 | E26: 5.24 | F26: 27.73 | G26: 1.95 | H26: 514 | I26: =H26/1000000 -> 0.000514 | J26: 1185 | K26: 114010 | L26: =K26/1000000 -> 0.11401 | M26: =K26/10000000000 -> 1.1401e-05 | N26: =H26/K26 -> 0.0045083765 | O26: =I26/M26 -> 45.083765 | P26: =J26/K26 -> 0.010393825 | Q26: 4.983 | R26: 20.09467 | S26: 22.527471 | T26: 72.774765 | U26: 110.25809 | V26: 171.31161 | W26: 247.43444 | X26: 0.29 | Y26: 5.28 | Z26: =Y26*X26 -> 1.5312
A27: JLA-JAK | B27: 1521 | C27: 156 | D27: 74 | E27: 6.2 | F27: 27.73 | G27: 1.92 | H27: 454 | I27: =H27/1000000 -> 0.000454 | J27: 1119 | K27: 114010 | L27: =K27/1000000 -> 0.11401 | M27: =K27/10000000000 -> 1.1401e-05 | N27: =H27/K27 -> 0.0039821068 | O27: =I27/M27 -> 39.821068 | P27: =J27/K27 -> 0.0098149285 | Q27: 4.049 | R27: 9.9183869 | S27: 21.20718 | T27: 52.078913 | U27: 107.78332 | V27: 130.47505 | W27: 215.10947
A28: JLA-JAK | B28: 1521 | C28: 156 | D28: 75 | E28: 8.63 | F28: 27.73 | G28: 2.11 | H28: 481 | I28: =H28/1000000 -> 0.000481 | J28: 1012 | K28: 114010 | L28: =K28/1000000 -> 0.11401 | M28: =K28/10000000000 -> 1.1401e-05 | N28: =H28/K28 -> 0.0042189282 | O28: =I28/M28 -> 42.189282 | P28: =J28/K28 -> 0.0088764143 | Q28: 4.45 | R28: 18.228777 | S28: 20.91483 | T28: 64.770507 | U28: 99.248058 | V28: 149.55825 | W28: 237.9426
A29: JLA-JAK | B29: 1521 | C29: 157 | D29: 67 | E29: 7.72 | F29: 27.73 | G29: 2.34 | H29: 376 | I29: =H29/1000000 -> 0.000376 | J29: 827 | K29: 114010 | L29: =K29/1000000 -> 0.11401 | M29: =K29/10000000000 -> 1.1401e-05 | N29: =H29/K29 -> 0.0032979563 | O29: =I29/M29 -> 32.979563 | P29: =J29/K29 -> 0.0072537497 | Q29: 4.369 | R29: 12.119463 | S29: 19.41279 | T29: 36.85638 | U29: 110.33186 | V29: 115.49938 | W29: 218.97265
A30: JLA-JAK | B30: 1521 | C30: 157 | D30: 68 | E30: 7.08 | F30: 27.73 | G30: 2.36 | H30: 340 | I30: =H30/1000000 -> 0.00034 | J30: 948 | K30: 114010 | L30: =K30/1000000 -> 0.11401 | M30: =K30/10000000000 -> 1.1401e-05 | N30: =H30/K30 -> 0.0029821945 | O30: =I30/M30 -> 29.821945 | P30: =J30/K30 -> 0.0083150601 | Q30: 4.224 | R30: 14.486637 | S30: 19.920498 | T30: 43.656191 | U30: 114.53535 | V30: 129.61092 | W30: 237.58271 | X30: 0.48 | Y30: 4.71 | Z30: =Y30*X30 -> 2.2608
A31: JLA-JAK | B31: 1521 | C31: 157 | D31: 72 | E31: 6.95 | F31: 27.73 | G31: 2.6 | H31: 345 | I31: =H31/1000000 -> 0.000345 | J31: 910 | K31: 114010 | L31: =K31/1000000 -> 0.11401 | M31: =K31/10000000000 -> 1.1401e-05 | N31: =H31/K31 -> 0.0030260503 | O31: =I31/M31 -> 30.260503 | P31: =J31/K31 -> 0.007981756 | Q31: 6.1 | R31: 14.92541 | S31: 24.306774 | T31: 58.512313 | U31: 153.00181 | V31: 152.84734 | W31: 363.3352
A32: JLA-JAK | B32: 1521 | C32: 158 | D32: 70 | E32: 7.79 | F32: 27.73 | G32: 1.44 | H32: 523 | I32: =H32/1000000 -> 0.000523 | J32: 437 | K32: 114010 | L32: =K32/1000000 -> 0.11401 | M32: =K32/10000000000 -> 1.1401e-05 | N32: =H32/K32 -> 0.0045873169 | O32: =I32/M32 -> 45.873169 | P32: =J32/K32 -> 0.0038329971 | Q32: 3.417 | R32: 19.411764 | S32: 22.631666 | T32: 64.644144 | U32: 109.25982 | V32: 153.29039 | W32: 224.76697
A33: JLA-JAK | B33: 1521 | C33: 158 | D33: 73 | E33: 6.96 | F33: 27.73 | G33: 1.76 | H33: 454 | I33: =H33/1000000 -> 0.000454 | J33: 651 | K33: 114010 | L33: =K33/1000000 -> 0.11401 | M33: =K33/10000000000 -> 1.1401e-05 | N33: =H33/K33 -> 0.0039821068 | O33: =I33/M33 -> 39.821068 | P33: =J33/K33 -> 0.0057100254 | Q33: 4.613 | R33: 11.474232 | S33: 22.864113 | T33: 39.282754 | U33: 113.8069 | V33: 96.14417 | W33: 241.34715 | X33: 4.92 | Y33: 0.15 | Z33: =Y33*X33 -> 0.738
A34: JLA-JAK | B34: 1521 | C34: 158 | D34: 81 | E34: 9.81 | F34: 27.73 | G34: 1.48 | H34: 266 | I34: =H34/1000000 -> 0.000266 | J34: 577 | K34: 114010 | L34: =K34/1000000 -> 0.11401 | M34: =K34/10000000000 -> 1.1401e-05 | N34: =H34/K34 -> 0.0023331287 | O34: =I34/M34 -> 23.331287 | P34: =J34/K34 -> 0.0050609596 | Q34: 3.869 | R34: 13.977251 | S34: 23.34123 | T34: 56.133607 | U34: 116.3689 | V34: 131.95716 | W34: 247.76855
A35: MEAN | B35: =AVERAGE(B20:B34) -> 1521 | C35: =AVERAGE(C20:C34) -> 155.8 | D35: =AVERAGE(D20:D34) -> 71.866667 | E35: =AVERAGE(E20:E34) -> 7.5206667 | F35: =AVERAGE(F20:F34) -> 27.73 | G35: =AVERAGE(G20:G34) -> 1.8786667 | H35: =AVERAGE(H20:H34) -> 424.33333 | I35: =AVERAGE(I20:I34) -> 0.00042433333 | ... W35: =AVERAGE(W20:W34) -> 232.71224
A36: STDERR | B36: =STDEV(B20:B34)/SQRT(COUNT(B20:B34)) -> 0 | C36: =STDEV(C20:C34)/SQRT(COUNT(C20:C34)) -> 0.45981363 | D36: =STDEV(D20:D34)/SQRT(COUNT(D20:D34)) -> 1.8123036 | E36: =STDEV(E20:E34)/SQRT(COUNT(E20:E34)) -> 0.27464343 | F36: =STDEV(F20:F34)/SQRT(COUNT(F20:F34)) -> 9.4950267e-16 | G36: =STDEV(G20:G34)/SQRT(COUNT(G20:G34)) -> 0.099913613 | H36: =STDEV(H20:H34)/SQRT(COUNT(H20:H34)) -> 30.101047 | I36: =STDEV(I20:I34)/SQRT(COUNT(I20:I34)) -> 3.0101047e-05 | ... W36: =STDEV(W20:W34)/SQRT(COUNT(W20:W34)) -> 12.225886
A37: NRV-NEW | B37: 666 | C37: 101 | D37: 1 | E37: 8.59 | F37: 27.73 | G37: 1.18 | H37: 452 | I37: =H37/1000000 -> 0.000452 | J37: 754 | K37: 114010 | L37: =K37/1000000 -> 0.11401 | M37: =K37/10000000000 -> 1.1401e-05 | N37: =H37/K37 -> 0.0039645645 | O37: =I37/M37 -> 39.645645 | P37: =J37/K37 -> 0.006613455 | Q37: 3.251 | R37: 24.755789 | S37: 24.30566 | T37: 83.842244 | U37: 101.94143 | V37: 205.61117 | W37: 217.07178
A38: NRV-NEW | B38: 666 | C38: 101 | D38: 2 | E38: 8.54 | F38: 27.73 | G38: 1.59 | H38: 456 | I38: =H38/1000000 -> 0.000456 | J38: 827 | K38: 114010 | L38: =K38/1000000 -> 0.11401 | M38: =K38/10000000000 -> 1.1401e-05 | N38: =H38/K38 -> 0.0039996492 | O38: =I38/M38 -> 39.996492 | P38: =J38/K38 -> 0.0072537497 | Q38: 3.445 | R38: 26.173964 | S38: 29.016015 | T38: 85.487344 | U38: 113.55045 | V38: 205.69953 | W38: 242.18005
A39: NRV-NEW | B39: 666 | C39: 101 | D39: 3 | E39: 8.66 | F39: 27.73 | G39: 1.67 | H39: 493 | I39: =H39/1000000 -> 0.000493 | J39: 850 | K39: 114010 | L39: =K39/1000000 -> 0.11401 | M39: =K39/10000000000 -> 1.1401e-05 | N39: =H39/K39 -> 0.0043241821 | O39: =I39/M39 -> 43.241821 | P39: =J39/K39 -> 0.0074554864 | Q39: 3.033 | R39: 24.346542 | S39: 28.062841 | T39: 77.85441 | U39: 118.92943 | V39: 198.22718 | W39: 254.11305 | X39: 6.31 | Y39: 1.01 | Z39: =Y39*X39 -> 6.3731
A40: NRV-NEW | B40: 666 | C40: 105 | D40: 7 | E40: 6.93 | F40: 27.73 | G40: 1.4 | H40: 368 | I40: =H40/1000000 -> 0.000368 | J40: 591 | K40: 114010 | L40: =K40/1000000 -> 0.11401 | M40: =K40/10000000000 -> 1.1401e-05 | N40: =H40/K40 -> 0.003227787 | O40: =I40/M40 -> 32.27787 | P40: =J40/K40 -> 0.0051837558 | Q40: 3.903 | R40: 25.547176 | S40: 24.560371 | T40: 92.324842 | U40: 89.700536 | V40: 216.47908 | W40: 189.47632
...

Sheet weibull
A1: Population | B1: estimate_P12 | C1: estimate_P50 | D1: conf.low_P12 | E1: conf.low_P50 | F1: conf.high_P12 | G1: conf.high_P50 | H1: c | I1: b | J1: conf.low_c | K1: conf.low_b | L1: conf.high_c | M1: conf.high_b
A2: CCR-COL | B2: 2.2187969 | C2: 2.570942 | D2: 2.082266 | E2: 2.4309004 | F2: 2.363345 | G2: 2.7109626 | H2: 11.476114 | I2: 2.6543754 | J2: 10.920286 | K2: 2.5138723 | L2: 12.319222 | M2: 2.792829
A3: JLA-JAK | B3: 2.2801423 | C3: 2.633342 | D3: 2.1276005 | E3: 2.4818099 | F3: 2.4363308 | G3: 2.7918231 | H3: 11.738389 | I3: 2.7168611 | J3: 10.977848 | K3: 2.5660677 | L3: 12.411847 | M3: 2.8754929
A4: NRV-NEW | B4: 2.3076028 | C4: 2.6608803 | D4: 2.1627234 | E4: 2.5162266 | F4: 2.4537921 | G4: 2.8094895 | H4: 11.867612 | I4: 2.7443396 | J4: 11.166462 | K4: 2.6001862 | L4: 12.488276 | M4: 2.8931658
A5: TSZ-SAN | B5: 2.3715587 | C5: 2.7255272 | D5: 2.2012472 | E5: 2.5540012 | F5: 2.5416603 | G5: 2.8953681 | H5: 12.151972 | I5: 2.8089834 | J5: 11.373436 | K5: 2.6376452 | L5: 12.974548 | M5: 2.9783243

Sheet Stem hydraulics
E1: hydraulics | F1: hydraulics
A2: population | B2: elevation | C2: genotype | D2: Replicate # | E2: i_cs | F2: i_bs
A3: CCR-COL | B3: 72 | C3: 156 | D3: 43
A4: CCR-COL | B4: 72 | C4: 156 | D4: 44 | E4: 3.2431342 | F4: 148.66184
A5: CCR-COL | B5: 72 | C5: 156 | D5: 45 | E5: 2.8948936 | F5: 1550.9622
A6: CCR-COL | B6: 72 | C6: 156 | D6: 45.2 | E6: 2.4490005 | F6: 505.55011
A7: CCR-COL | B7: 72 | C7: 156 | D7: 45.3 | E7: 2.4203682 | F7: 117.48775
A8: CCR-COL | B8: 72 | C8: 149 | D8: 46 | E8: 2.6538177 | F8: 219.89161
A9: CCR-COL | B9: 72 | C9: 149 | D9: 47 | E9: 2.5839133 | F9: 169.40251
A10: CCR-COL | B10: 72 | C10: 149 | D10: 48 | E10: 2.4787211 | F10: 210.58645
A11: CCR-COL | B11: 72 | C11: 152 | D11: 49 | E11: 2.0143297 | F11: 303.01448
A12: CCR-COL | B12: 72 | C12: 152 | D12: 49.2 | E12: 2.2050401 | F12: 158.22073
A13: CCR-COL | B13: 72 | C13: 152 | D13: 49.3 | E13: 2.0719625 | F13: 146.13969
A14: CCR-COL | B14: 72 | C14: 152 | D14: 50
A15: CCR-COL | B15: 72 | C15: 152 | D15: 51 | E15: 2.586287 | F15: 438.32928
A16: CCR-COL | B16: 72 | C16: 155 | D16: 58 | E16: 2.5314449 | F16: 324.0905
A17: CCR-COL | B17: 72 | C17: 155 | D17: 59 | E17: 2.291759 | F17: 157.24154
A18: CCR-COL | B18: 72 | C18: 155 | D18: 60 | E18: 2.61816 | F18: 141.14386
A19: CCR-COL | B19: 72 | C19: 5 | D19: 61 | E19: 2.6585826 | F19: 159.39441
A20: CCR-COL | B20: 72 | C20: 5 | D20: 61.2 | E20: 2.436813 | F20: 113.97791
A21: CCR-COL | B21: 72 | C21: 5 | D21: 63 | E21: 2.1942131 | F21: 154.96232
A22: CCR-COL | B22: 72 | C22: 5 | D22: 63.2 | E22: 2.8392009 | F22: 93.089392
A23: CCR-COL | B23: 72 | C23: 5 | D23: 63.3 | E23: 2.8530227 | F23: 200.74332
A24: CCR-COL | B24: 72 | C24: 5 | D24: 85
A25: JLA-JAK | B25: 1521 | C25: 155 | D25: 62 | E25: 2.7299709 | F25: 126.94617
A26: JLA-JAK | B26: 1521 | C26: 155 | D26: 64 | E26: 2.1565863 | F26: 290.45873
A27: JLA-JAK | B27: 1521 | C27: 155 | D27: 66 | E27: 2.5483491 | F27: 154.25121
A28: JLA-JAK | B28: 1521 | C28: 157 | D28: 67 | E28: 2.5470854 | F28: 134.44298
A29: JLA-JAK | B29: 1521 | C29: 157 | D29: 68 | E29: 2.8784065 | F29: 136.54064
A30: JLA-JAK | B30: 1521 | C30: 153 | D30: 69 | E30: 2.5464056 | F30: 192.58826
A31: JLA-JAK | B31: 1521 | C31: 158 | D31: 70 | E31: 2.485128 | F31: 94.669456
A32: JLA-JAK | B32: 1521 | C32: 156 | D32: 71 | E32: 2.6157444 | F32: 110.02566
A33: JLA-JAK | B33: 1521 | C33: 157 | D33: 72 | E33: 2.7551149 | F33: 172.30279
A34: JLA-JAK | B34: 1521 | C34: 158 | D34: 73 | E34: 2.778385 | F34: 99.142061
A35: JLA-JAK | B35: 1521 | C35: 156 | D35: 74 | E35: 2.770292 | F35: 157.94117
A36: JLA-JAK | B36: 1521 | C36: 156 | D36: 75 | E36: 2.4846565 | F36: 98.847104
... A43: NRV-NEW | B43: 666 | C43: 101 | D43: 2 | E43: 3.3199144 | F43: 117.34662
A44: NRV-NEW | B44: 666 | C44: 101 | D44: 3
A45: NRV-NEW | B45: 666 | C45: 105 | D45: 7 | E45: 2.1787422 | F45: 297.19866
A46: NRV-NEW | B46: 666 | C46: 105 | D46: 7.2 | E46: 2.2261333 | F46: 97.506586
...
